from django.urls import reverse
from django.urls import resolve
from django.test import TestCase

from .forms import NewTopicForm
from .views import home

class NewTopicTests(TestCase):
    # ... other tests4

    def test_contains_form(self):  # <- new test
        url = reverse('new_topic', kwargs={'pk': 1})
        response = self.client.get(url)
        form = response.context.get('form')
        self.assertIsInstance(form, NewTopicForm)

    def test_new_topic_invalid_post_data(self):  # <- updated this one
        '''
        Invalid post data should not redirect
        The expected behavior is to show the form again with validation errors
        '''
        url = reverse('new_topic', kwargs={'pk': 1})
        response = self.client.post(url, {})
        form = response.context.get('form')
        self.assertEquals(response.status_code, 200)
        self.assertTrue(form.errors)
